Workbook

Sheet 人物卡
E1: 建议以office2010及以上或WPS打开此表
C2: 调查员信息 | S2: 此处应有头像
C3: 角色名 | G3: 性别 | J3: 精神疾病 | L3: 暂无 | N3: 心智 | O3: =V33 -> 4 | Q3: ="/"&U33 -> /4
C4: 玩家 | G4: 年龄 | J4: 坚毅状态 | L4: 正常 | N4: 坚毅 | O4: =V34 -> 1 | Q4: ="/"&U34 -> /1
C5: 动力 | J5: 健康状态 | L5: 健康 | N5: 健康 | O5: =V26 -> 1 | Q5: ="/"&U26 -> /1
C6: 职业编号 | E6: 0 | F6: =VLOOKUP(人物卡!E6,职业列表!A2:D25,2,FALSE) -> 职业 | J6: 经济情况
C7: 心智支柱 | J7: 经济阶层 | L7: =IF(N20>=7,"非常富有",LOOKUP(N20,{0,1,2,3,4,5,6},{"贫穷","底层阶级","工人阶级","中产阶级下层","中产阶级","中产阶级上层","上层阶级"})) -> 贫穷 | N7: 年收入 | O7: =IF(N20>=7,"$75,000+",LOOKUP(N20,{0,1,2,3,4,5,6},{"$0-$150","$150-$250","$250-$1,250","$1,250-$1,500","$1,500-$3,000","$3,000-$10,000","$10,000-$75,000"})) -> $0-$150
J8: 典型标志 | L8: =IF(N20>=7,信誉等级!C9,IF(N20>=6,信誉等级!C8,IF(N20>=5,信誉等级!C7,IF(N20>=4,信誉等级!C6,IF(N20>=3,信誉等级!C5,IF(N20>=2,信誉等级!C4,IF(N20>=1,信誉等级!C3,IF(N20>=0,信誉等级!C2,"信誉异常！")))))))) -> 流浪汉；衣衫褴褛；居无定所；接受救济；拾荒
C10: 能力点数 | S10: 战斗 | T10: 基础 | U10: 其他 | V10: 等级
C11: 调查能力 | G11: 剩余 | H11: =E11-SUM(F16:F47,M16:M27,M30:M48,S40:S48) -> 0 | S11: 命中阀值 | T11: =IF(U16>=8,4,3) -> 3 | V11: =SUM(T11:U12) -> 3
C12: 一般能力 | G12: 剩余 | H12: =E12-SUM(T16:T48) -> 0
C13: ="["&VLOOKUP(人物卡!E6,职业列表!A2:D25,2,FALSE)&"]"&"的职业能力:"&VLOOKUP(人物卡!E6,职业列表!A2:D25,4,FALSE)&" 信誉等级:"&VLOOKUP(人物卡!E6,职业列表!A2:D25,3,FALSE) -> [职业]的职业能力:请在职业列表自行选择职业编号 信誉等级:自动
C14: 学术能力 | J14: 社交能力 | Q14: 一般能力
C15: 能力 | E15: 本职 | F15: 调查 | G15: 等级 | H15: 剩余 | J15: 能力 | L15: 本职 | M15: 调查 | N15: 等级 | O15: 剩余 | Q15: 能力 | S15: 本职 | T15: 一般 | U15: 等级 | V15: 剩余
C16: 会计 | E16: =IFERROR(IF(COUNTIF(职业!$U$4:$U$13,人物卡!C16)=1,"☑","☐"),"") -> ☐ | G16: =IF(E16="☑",F16*2,F16) -> 0 | H16: =G16 -> 0 | J16: 察言观色 | L16: =IFERROR(IF(COUNTIF(职业!$U$4:$U$13,人物卡!J16)=1,"☑","☐"),"") -> ☐ | N16: =IF(L16="☑",M16*2,M16) -> 0 | O16: =N16 -> 0 | Q16: 运动 | S16: =IFERROR(IF(COUNTIF(职业!$U$4:$U$13,人物卡!Q16)=1,"☑","☐"),"") -> ☐ | U16: =IF($S16="☑",$T16*2,$T16) -> 0 | V16: =U16 -> 0
C17: 人类学 | E17: =IFERROR(IF(COUNTIF(职业!$U$4:$U$13,人物卡!C17)=1,"☑","☐"),"") -> ☐ | G17: =IF(E17="☑",F17*2,F17) -> 0 | H17: =G17 -> 0 | J17: 议价 | L17: =IFERROR(IF(COUNTIF(职业!$U$4:$U$13,人物卡!J17)=1,"☑","☐"),"") -> ☐ | N17: =IF(L17="☑",M17*2,M17) -> 0 | O17: =N17 -> 0 | Q17: 藏匿 | S17: =IFERROR(IF(COUNTIF(职业!$U$4:$U$13,人物卡!Q17)=1,"☑","☐"),"") -> ☐ | U17: =IF($S17="☑",$T17*2,$T17) -> 0 | V17: =U17 -> 0
C18: 考古学 | E18: =IFERROR(IF(COUNTIF(职业!$U$4:$U$13,人物卡!C18)=1,"☑","☐"),"") -> ☐ | G18: =IF(E18="☑",F18*2,F18) -> 0 | H18: =G18 -> 0 | J18: 官僚 | L18: =IFERROR(IF(COUNTIF(职业!$U$4:$U$13,人物卡!J18)=1,"☑","☐"),"") -> ☐ | N18: =IF(L18="☑",M18*2,M18) -> 0 | O18: =N18 -> 0 | Q18: 伪装 | S18: =IFERROR(IF(COUNTIF(职业!$U$4:$U$13,人物卡!Q18)=1,"☑","☐"),"") -> ☐ | U18: =IF($S18="☑",$T18*2,$T18) -> 0 | V18: =U18 -> 0
C19: 建筑学 | E19: =IFERROR(IF(COUNTIF(职业!$U$4:$U$13,人物卡!C19)=1,"☑","☐"),"") -> ☐ | G19: =IF(E19="☑",F19*2,F19) -> 0 | H19: =G19 -> 0 | J19: 警方交谈 | L19: =IFERROR(IF(COUNTIF(职业!$U$4:$U$13,人物卡!J19)=1,"☑","☐"),"") -> ☐ | N19: =IF(L19="☑",M19*2,M19) -> 0 | O19: =N19 -> 0 | Q19: 驾驶 | S19: =IFERROR(IF(COUNTIF(职业!$U$4:$U$13,人物卡!Q19)=1,"☑","☐"),"") -> ☐ | U19: =IF($S19="☑",$T19*2,$T19) -> 0 | V19: =U19 -> 0
C20: 艺术史 | E20: =IFERROR(IF(COUNTIF(职业!$U$4:$U$13,人物卡!C20)=1,"☑","☐"),"") -> ☐ | G20: =IF(E20="☑",F20*2,F20) -> 0 | H20: =G20 -> 0 | J20: 信誉等级 | L20: =IFERROR(VLOOKUP(E6,职业!A3:E25,3,FALSE),0) -> 0 | N20: =IF(L20=0,M20,IF(E6=职业!A12,0,IF(E6=职业!A10,L20+M20*2,IF((M20+L20-VLOOKUP(人物卡!E6,职业!A1:E25,5,FALSE))<=0,L20+M20,ROUND((VLOOKUP(人物卡!E6,职业!A1:E25,5,FALSE)+(M20+L20-VLOOKUP(人物卡!E6,职业!A1:E25,5,FALSE))/2)-0.1,))))) -> 0 | O20: =N20 -> 0 | Q20: 电器维修 | S20: =IFERROR(IF(COUNTIF(职业!$U$4:$U$13,人物卡!Q20)=1,"☑","☐"),"") -> ☐ | U20: =IF($S20="☑",$T20*2,$T20) -> 0 | V20: =U20 -> 0
C21: 生物学 | E21: =IFERROR(IF(COUNTIF(职业!$U$4:$U$13,人物卡!C21)=1,"☑","☐"),"") -> ☐ | G21: =IF(E21="☑",F21*2,F21) -> 0 | H21: =G21 -> 0 | J21: 奉承 | L21: =IFERROR(IF(COUNTIF(职业!$U$4:$U$13,人物卡!J21)=1,"☑","☐"),"") -> ☐ | N21: =IF(L21="☑",M21*2,M21) -> 0 | O21: =N21 -> 0 | Q21: 爆破 | S21: =IFERROR(IF(COUNTIF(职业!$U$4:$U$13,人物卡!Q21)=1,"☑","☐"),"") -> ☐ | U21: =IF($S21="☑",$T21*2,$T21) -> 0 | V21: =U21 -> 0
C22: 克苏鲁神话 | E22: —— | G22: =F22 -> 0 | H22: =G22 -> 0 | J22: 审讯 | L22: =IFERROR(IF(COUNTIF(职业!$U$4:$U$13,人物卡!J22)=1,"☑","☐"),"") -> ☐ | N22: =IF(L22="☑",M22*2,M22) -> 0 | O22: =N22 -> 0 | Q22: 偷窃 | S22: =IFERROR(IF(COUNTIF(职业!$U$4:$U$13,人物卡!Q22)=1,"☑","☐"),"") -> ☐ | U22: =IF($S22="☑",$T22*2,$T22) -> 0 | V22: =U22 -> 0
C23: 密码学 | E23: =IFERROR(IF(COUNTIF(职业!$U$4:$U$13,人物卡!C23)=1,"☑","☐"),"") -> ☐ | G23: =IF(E23="☑",F23*2,F23) -> 0 | H23: =G23 -> 0 | J23: 威胁 | L23: =IFERROR(IF(COUNTIF(职业!$U$4:$U$13,人物卡!J23)=1,"☑","☐"),"") -> ☐ | N23: =IF(L23="☑",M23*2,M23) -> 0 | O23: =N23 -> 0 | Q23: 枪械 | S23: =IFERROR(IF(COUNTIF(职业!$U$4:$U$13,人物卡!Q23)=1,"☑","☐"),"") -> ☐ | U23: =IF($S23="☑",$T23*2,$T23) -> 0 | V23: =U23 -> 0
C24: 地质学 | E24: =IFERROR(IF(COUNTIF(职业!$U$4:$U$13,人物卡!C24)=1,"☑","☐"),"") -> ☐ | G24: =IF(E24="☑",F24*2,F24) -> 0 | H24: =G24 -> 0 | J24: 口述采访 | L24: =IFERROR(IF(COUNTIF(职业!$U$4:$U$13,人物卡!J24)=1,"☑","☐"),"") -> ☐ | N24: =IF(L24="☑",M24*2,M24) -> 0 | O24: =N24 -> 0 | Q24: 急救 | S24: =IFERROR(IF(COUNTIF(职业!$U$4:$U$13,人物卡!Q24)=1,"☑","☐"),"") -> ☐ | U24: =IF($S24="☑",$T24*2,$T24) -> 0 | V24: =U24 -> 0
C25: 历史 | E25: =IFERROR(IF(COUNTIF(职业!$U$4:$U$13,人物卡!C25)=1,"☑","☐"),"") -> ☐ | G25: =IF(E25="☑",F25*2,F25) -> 0 | H25: =G25 -> 0 | J25: 安抚 | L25: =IFERROR(IF(COUNTIF(职业!$U$4:$U$13,人物卡!J25)=1,"☑","☐"),"") -> ☐ | N25: =IF(L25="☑",M25*2,M25) -> 0 | O25: =N25 -> 0 | Q25: 逃脱 | S25: =IFERROR(IF(COUNTIF(职业!$U$4:$U$13,人物卡!Q25)=1,"☑","☐"),"") -> ☐ | U25: =IF(T16=0,T25*2,IF((T25/T16)>=2,(T25-T16*2)*2+T25-(T25-T16*2),T25)) -> 0 | V25: =U25 -> 0
C26: 语言 | E26: =IFERROR(IF(COUNTIF(职业!$U$4:$U$13,人物卡!C26)=1,"☑","☐"),"") -> ☐ | G26: =IF(E26="☑",F26*2,F26) -> 0 | H26: =G26 -> 0 | J26: 底层社会 | L26: =IFERROR(IF(COUNTIF(职业!$U$4:$U$13,人物卡!J26)=1,"☑","☐"),"") -> ☐ | N26: =IF(L26="☑",M26*2,M26) -> 0 | O26: =N26 -> 0 | Q26: 健康 | S26: 1 | U26: =IF(S26=1,1+T26,T26*2) -> 1 | V26: =U26 -> 1
C27: 法律 | E27: =IFERROR(IF(COUNTIF(职业!$U$4:$U$13,人物卡!C27)=1,"☑","☐"),"") -> ☐ | G27: =IF(E27="☑",F27*2,F27) -> 0 | H27: =G27 -> 0 | J27: 如果存在二选一能力，请自己勾选 | Q27: 催眠 | S27: =IFERROR(IF(COUNTIF(职业!$U$4:$U$13,人物卡!Q27)=1,"☑","☐"),"") -> ☐ | U27: =IF($S27="☑",$T27*2,$T27) -> 0 | V27: =U27 -> 0
C28: 文献查阅 | E28: =IFERROR(IF(COUNTIF(职业!$U$4:$U$13,人物卡!C28)=1,"☑","☐"),"") -> ☐ | G28: =IF(E28="☑",F28*2,F28) -> 0 | H28: =G28 -> 0 | J28: 技术能力 | Q28: 机械维修 | S28: =IFERROR(IF(COUNTIF(职业!$U$4:$U$13,人物卡!Q28)=1,"☑","☐"),"") -> ☐ | U28: =IF($S28="☑",$T28*2,$T28) -> 0 | V28: =U28 -> 0
C29: 医学 | E29: =IFERROR(IF(COUNTIF(职业!$U$4:$U$13,人物卡!C29)=1,"☑","☐"),"") -> ☐ | G29: =IF(E29="☑",F29*2,F29) -> 0 | H29: =G29 -> 0 | J29: 能力 | L29: 本职 | M29: 调查 | N29: 等级 | O29: 剩余 | Q29: 导航 | S29: =IFERROR(IF(COUNTIF(职业!$U$4:$U$13,人物卡!Q29)=1,"☑","☐"),"") -> ☐ | U29: =IF($S29="☑",$T29*2,$T29) -> 0 | V29: =U29 -> 0
C30: 神秘学 | E30: =IFERROR(IF(COUNTIF(职业!$U$4:$U$13,人物卡!C30)=1,"☑","☐"),"") -> ☐ | G30: =IF(E30="☑",F30*2,F30) -> 0 | H30: =G30 -> 0 | J30: 艺术 | L30: =IFERROR(IF(COUNTIF(职业!$U$4:$U$13,人物卡!J30)=1,"☑","☐"),"") -> ☐ | N30: =IF(L30="☑",M30*2,M30) -> 0 | O30: =N30 -> 0 | Q30: 物品整备 | S30: =IFERROR(IF(COUNTIF(职业!$U$4:$U$13,人物卡!Q30)=1,"☑","☐"),"") -> ☐ | U30: =IF($S30="☑",$T30*2,$T30) -> 0 | V30: =U30 -> 0
C31: 物理学 | E31: =IFERROR(IF(COUNTIF(职业!$U$4:$U$13,人物卡!C31)=1,"☑","☐"),"") -> ☐ | G31: =IF(E31="☑",F31*2,F31) -> 0 | H31: =G31 -> 0 | J31: 天文学 | L31: =IFERROR(IF(COUNTIF(职业!$U$4:$U$13,人物卡!J31)=1,"☑","☐"),"") -> ☐ | N31: =IF(L31="☑",M31*2,M31) -> 0 | O31: =N31 -> 0 | Q31: 精神分析 | S31: =IFERROR(IF(COUNTIF(职业!$U$4:$U$13,人物卡!Q31)=1,"☑","☐"),"") -> ☐ | U31: =IF($S31="☑",$T31*2,$T31) -> 0 | V31: =U31 -> 0
C32: 神学 | E32: =IFERROR(IF(COUNTIF(职业!$U$4:$U$13,人物卡!C32)=1,"☑","☐"),"") -> ☐ | G32: =IF(E32="☑",F32*2,F32) -> 0 | H32: =G32 -> 0 | J32: 化学 | L32: =IFERROR(IF(COUNTIF(职业!$U$4:$U$13,人物卡!J32)=1,"☑","☐"),"") -> ☐ | N32: =IF(L32="☑",M32*2,M32) -> 0 | O32: =N32 -> 0 | Q32: 骑术 | S32: =IFERROR(IF(COUNTIF(职业!$U$4:$U$13,人物卡!Q32)=1,"☑","☐"),"") -> ☐ | U32: =IF($S32="☑",$T32*2,$T32) -> 0 | V32: =U32 -> 0
J33: 手艺 | L33: =IFERROR(IF(COUNTIF(职业!$U$4:$U$13,人物卡!J33)=1,"☑","☐"),"") -> ☐ | N33: =IF(L33="☑",M33*2,M33) -> 0 | O33: =N33 -> 0 | Q33: 心智 | S33: 4 | U33: =IF(S33=4,T33+4,T33*2) -> 4 | V33: =U33 -> 4
C34: ="任意社交能力数："&IF(SUMIF(职业!$U$4:$U$13,J40,职业!$V$4:$V$13)=0,"无",SUMIF(职业!$U$4:$U$13,J40,职业!$V$4:$V$13)) -> 任意社交能力数：无 | J34: 证物采集 | L34: =IFERROR(IF(COUNTIF(职业!$U$4:$U$13,人物卡!J34)=1,"☑","☐"),"") -> ☐ | N34: =IF(L34="☑",M34*2,M34) -> 0 | O34: =N34 -> 0 | Q34: 坚毅 | S34: 1 | U34: =IF(S34=1,T34+1,T34*2) -> 1 | V34: =U34 -> 1
C35: ="任意学术能力数："&IF(SUMIF(职业!$U$4:$U$13,K40,职业!$V$4:$V$13)=0,"无",SUMIF(职业!$U$4:$U$13,K40,职业!$V$4:$V$13)) -> 任意学术能力数：无 | J35: 法医 | L35: =IFERROR(IF(COUNTIF(职业!$U$4:$U$13,人物卡!J35)=1,"☑","☐"),"") -> ☐ | N35: =IF(L35="☑",M35*2,M35) -> 0 | O35: =N35 -> 0 | Q35: 搏击 | S35: =IFERROR(IF(COUNTIF(职业!$U$4:$U$13,人物卡!Q35)=1,"☑","☐"),"") -> ☐ | U35: =IF($S35="☑",$T35*2,$T35) -> 0 | V35: =U35 -> 0
C36: ="任意调查能力数："&IF(SUMIF(职业!$U$4:$U$13,L40,职业!$V$4:$V$13)=0,"无",SUMIF(职业!$U$4:$U$13,L40,职业!$V$4:$V$13)) -> 任意调查能力数：无 | J36: 开锁 | L36: =IFERROR(IF(COUNTIF(职业!$U$4:$U$13,人物卡!J36)=1,"☑","☐"),"") -> ☐ | N36: =IF(L36="☑",M36*2,M36) -> 0 | O36: =N36 -> 0 | Q36: 警觉 | S36: =IFERROR(IF(COUNTIF(职业!$U$4:$U$13,人物卡!Q36)=1,"☑","☐"),"") -> ☐ | U36: =IF($S36="☑",$T36*2,$T36) -> 0 | V36: =U36 -> 0
C37: ="任意学术或社交能力数："&IF(SUMIF(职业!$U$4:$U$13,M40,职业!$V$4:$V$13)=0,"无",SUMIF(职业!$U$4:$U$13,M40,职业!$V$4:$V$13)) -> 任意学术或社交能力数：无 | J37: 野外求生 | L37: =IFERROR(IF(COUNTIF(职业!$U$4:$U$13,人物卡!J37)=1,"☑","☐"),"") -> ☐ | N37: =IF(L37="☑",M37*2,M37) -> 0 | O37: =N37 -> 0 | Q37: 追踪 | S37: =IFERROR(IF(COUNTIF(职业!$U$4:$U$13,人物卡!Q37)=1,"☑","☐"),"") -> ☐ | U37: =IF($S37="☑",$T37*2,$T37) -> 0 | V37: =U37 -> 0
C38: ="任意社交或技术能力数："&IF(SUMIF(职业!$U$4:$U$13,N40,职业!$V$4:$V$13)=0,"无",SUMIF(职业!$U$4:$U$13,N40,职业!$V$4:$V$13)) -> 任意社交或技术能力数：无 | J38: 药剂学 | L38: =IFERROR(IF(COUNTIF(职业!$U$4:$U$13,人物卡!J38)=1,"☑","☐"),"") -> ☐ | N38: =IF(L38="☑",M38*2,M38) -> 0 | O38: =N38 -> 0 | Q38: 潜行 | S38: =IFERROR(IF(COUNTIF(职业!$U$4:$U$13,人物卡!Q38)=1,"☑","☐"),"") -> ☐ | U38: =IF($S38="☑",$T38*2,$T38) -> 0 | V38: =U38 -> 0
C39: ="任意能力数："&IF(SUMIF(职业!$U$4:$U$13,O40,职业!$V$4:$V$13)=0,"无",SUMIF(职业!$U$4:$U$13,O40,职业!$V$4:$V$13)) -> 任意能力数：无 | J39: 摄影 | L39: =IFERROR(IF(COUNTIF(职业!$U$4:$U$13,人物卡!J39)=1,"☑","☐"),"") -> ☐ | N39: =IF(L39="☑",M39*2,M39) -> 0 | O39: =N39 -> 0 | Q39: 近战武器 | S39: =IFERROR(IF(COUNTIF(职业!$U$4:$U$13,人物卡!Q39)=1,"☑","☐"),"") -> ☐ | U39: =IF($S39="☑",$T39*2,$T39) -> 0 | V39: =U39 -> 0
J40: 社交 | K40: 学术 | L40: 调查 | M40: 学术或社交 | N40: 社交或技术 | O40: 任意
C41: 战斗
...

Sheet 职业列表
A1: 序号 | B1: 职业列表 | C1: 信誉等级 | D1: 职业技能
A2: 0 | B2: 职业 | C2: 自动 | D2: 请在职业列表自行选择职业编号
A3: 1 | B3: 精神病学家 | C3: =职业!C3&职业!D3&职业!E3 -> 3~4 | D3: 生物学 、语言 、文献查阅 、医学 、药剂学 、精神分析 、察言观色 、任意2个社交能力
A4: 2 | B4: ▽古玩家 | C4: =职业!C4&职业!D4&职业!E4 -> 2~5 | D4: 建筑学 、艺术史 、议价 、历史 、语言 、法律 、文献查阅 、任意1个调查能力
A5: 3 | B5: 考古学家 | C5: =职业!C5&职业!D5&职业!E5 -> 4~5 | D5: 考古学 、运动 、证物采集 、急救 、历史 、语言 、文献查阅 、骑术 、任意2个调查能力
A6: 4 | B6: ▽艺术家 | C6: =职业!C6&职业!D6&职业!E6 -> 1~4 | D6: 建筑学 、艺术史 、艺术 、手艺 、伪装 、奉承 、摄影 、察言观色 、任意2个学术或社交能力
A7: 5 | B7: ▽作家 | C7: =职业!C7&职业!D7&职业!E7 -> 1~3 | D7: 艺术 、历史 、语言 、文献查阅 、口述采访 、察言观色 、任意3个能力
A8: 6 | B8: 神职人员 | C8: =职业!C8&职业!D8&职业!E8 -> 2~5 | D8: 历史 、语言 、文献查阅 、精神分析 、察言观色 、安抚 、神学 、任意1个社交能力
A9: 7 | B9: 罪犯 | C9: =职业!C9&职业!D9&职业!E9 -> 0~4 | D9: 议价 、威胁 、开锁 、搏击 、警觉 、追踪 、潜行 、底层社会 、任意1个社交或技术能力
A10: 8 | B10: ▽风雅子弟 | C10: =职业!C10&职业!D10&职业!E10 -> 3+ | D10: 信誉等级 、奉承 、骑术 、任意5个能力
A11: 9 | B11: ▽医生 | C11: =职业!C11&职业!D11&职业!E11 -> 4~6 | D11: 会计 、生物学 、急救 、法医 、语言 、医学 、药剂学 、察言观色 、安抚
A12: 10 | B12: 流浪汉 | C12: =职业!C12&职业!D12&职业!E12 -> 0 | D12: 运动 、议价 、偷窃 、野外求生 、警觉 、潜行 、底层社会
A13: 11 | B13: ▽记者 | C13: =职业!C13&职业!D13&职业!E13 -> 2~4 | D13: 警方交谈 、伪装 、证物采集 、语言 、口述采访 、摄影 、察言观色 、安抚 、追踪 、任意1个社交能力
A14: 12 | B14: 军人 | C14: =职业!C14&职业!D14&职业!E14 -> 2~4 | D14: 运动 、枪械 、威胁 、野外求生 、搏击 、近战武器
... A25: 23 | B25: 科学家 | C25: =职业!C25&职业!D25&职业!E25 -> 3~4 | D25: 电器维修 、证物采集 、语言 、文献查阅 、摄影 、下列任选2：天文学、生物学、化学、密码学、法医、地质学、物理学

Sheet 示例 哈维先生
B2: 调查员姓名 | D2: 哈维·沃尔特 | I2: 心智 | K2: 6 | M2: ="/"&4+U32 -> /6 | P2: 此处应有头像
B3: 玩家 | D3: 秋叶EXODIS
B4: 动力 | D4: 好奇 | I4: 坚毅 | K4: 6 | M4: ="/"&1+U33 -> /6
B5: 职业 | D5: 记者
B6: 心智支柱 | D6: 宿命论 | I6: 健康 | K6: 8 | M6: ="/"&1+U25 -> /8
D7: 搜寻观测无定的预兆
I8: 职业特长 | K8: 使用安抚进入收藏旧报纸的资料库
B10: 创建点数 | D10: 18 | F10: 剩余 | G10: =D10-SUM(E15:E41,L15:L28,L30:L41,S15:S41) -> -8
B11: 一般能力点数 | D11: 65 | F11: 剩余 | G11: =D11-SUM(T15:T41) -> 20
B13: 学术能力 | I13: 社交能力 | P13: 一般能力
B14: 能力 | D14: 本职 | E14: 创建 | F14: 等级 | G14: 剩余 | I14: 能力 | K14: 本职 | L14: 创建 | M14: 等级 | N14: 剩余 | P14: 能力 | R14: 本职 | S14: 创建 | T14: 一般 | U14: 等级 | V14: 剩余
B15: 会计 | F15: =IF(D15=0,E15,E15*2) -> 0 | I15: 察言观色 | K15: √ | M15: =IF(K15=0,L15,L15*2) -> 0 | P15: 运动 | T15: 3 | U15: =IF(R15=0,S15+T15,S15*2+T15) -> 3
B16: 人类学 | F16: =IF(D16=0,E16,E16*2) -> 0 | I16: 议价 | M16: =IF(K16=0,L16,L16*2) -> 0 | P16: 藏匿 | U16: =IF(R16=0,S16+T16,S16*2+T16) -> 0
B17: 考古学 | E17: 4 | F17: =IF(D17=0,E17,E17*2) -> 4 | I17: 官僚 | K17: √ | M17: =IF(K17=0,L17,L17*2) -> 0 | P17: 伪装 | R17: √ | U17: =IF(R17=0,S17+T17,S17*2+T17) -> 0
B18: 建筑学 | F18: =IF(D18=0,E18,E18*2) -> 0 | I18: 警方交谈 | K18: √ | M18: =IF(K18=0,L18,L18*2) -> 0 | P18: 驾驶 | U18: =IF(R18=0,S18+T18,S18*2+T18) -> 0
B19: 艺术史 | F19: =IF(D19=0,E19,E19*2) -> 0 | I19: 信誉等级 | L19: 4 | M19: =IF(K19=0,L19,L19*2) -> 4 | P19: 电器维修 | U19: =IF(R19=0,S19+T19,S19*2+T19) -> 0
B20: 生物学 | F20: =IF(D20=0,E20,E20*2) -> 0 | I20: 奉承 | M20: =IF(K20=0,L20,L20*2) -> 0 | P20: 爆破 | U20: =IF(R20=0,S20+T20,S20*2+T20) -> 0
B21: 克苏鲁神话 | D21: —— | F21: =E21 -> 0 | I21: 审讯 | M21: =IF(K21=0,L21,L21*2) -> 0 | P21: 偷窃 | U21: =IF(R21=0,S21+T21,S21*2+T21) -> 0
B22: 密码学 | F22: =IF(D22=0,E22,E22*2) -> 0 | I22: 威胁 | M22: =IF(K22=0,L22,L22*2) -> 0 | P22: 枪械 | U22: =IF(R22=0,S22+T22,S22*2+T22) -> 0
B23: 地质学 | F23: =IF(D23=0,E23,E23*2) -> 0 | I23: 口述采访 | K23: √ | M23: =IF(K23=0,L23,L23*2) -> 0 | P23: 急救 | U23: =IF(R23=0,S23+T23,S23*2+T23) -> 0
B24: 历史 | F24: =IF(D24=0,E24,E24*2) -> 0 | I24: 安抚 | K24: √ | L24: 1 | M24: =IF(K24=0,L24,L24*2) -> 2 | P24: 逃脱 | R24: —— | T24: 3 | U24: =S24+T24 -> 3
B25: 语言 | D25: √ | E25: 3 | F25: =IF(D25=0,E25,E25*2) -> 6 | I25: 底层社会 | M25: =IF(K25=0,L25,L25*2) -> 0 | P25: 健康 | R25: —— | T25: 7 | U25: =S25+T25 -> 7
F26: =IF(D26=0,E26,E26*2) -> 0 | M26: =IF(K26=0,L26,L26*2) -> 0 | P26: 催眠 | U26: =IF(R26=0,S26+T26,S26*2+T26) -> 0
F27: =IF(D27=0,E27,E27*2) -> 0 | M27: =IF(K27=0,L27,L27*2) -> 0 | P27: 机械维修 | U27: =IF(R27=0,S27+T27,S27*2+T27) -> 0
F28: =IF(D28=0,E28,E28*2) -> 0 | M28: =IF(K28=0,L28,L28*2) -> 0 | P28: 导航 | U28: =IF(R28=0,S28+T28,S28*2+T28) -> 0
B29: 法律 | E29: 4 | F29: =IF(D29=0,E29,E29*2) -> 4 | I29: 技术能力 | P29: 物品整备 | T29: 4 | U29: =IF(R29=0,S29+T29,S29*2+T29) -> 4
B30: 文献查阅 | E30: 3 | F30: =IF(D30=0,E30,E30*2) -> 3 | I30: 艺术 | M30: =IF(K30=0,L30,L30*2) -> 0 | P30: 精神分析 | T30: 6 | U30: =IF(R30=0,S30+T30,S30*2+T30) -> 6
B31: 医学 | F31: =IF(D31=0,E31,E31*2) -> 0 | I31: 天文学 | M31: =IF(K31=0,L31,L31*2) -> 0 | P31: 骑术 | U31: =IF(R31=0,S31+T31,S31*2+T31) -> 0
B32: 神秘学 | E32: 2 | F32: =IF(D32=0,E32,E32*2) -> 2 | I32: 化学 | M32: =IF(K32=0,L32,L32*2) -> 0 | P32: 心智 | R32: —— | T32: 2 | U32: =S32+T32 -> 2
B33: 物理学 | F33: =IF(D33=0,E33,E33*2) -> 0 | I33: 手艺 | M33: =IF(K33=0,L33,L33*2) -> 0 | P33: 坚毅 | R33: —— | T33: 5 | U33: =S33+T33 -> 5
B34: 神学 | F34: =IF(D34=0,E34,E34*2) -> 0 | I34: 证物采集 | K34: √ | M34: =IF(K34=0,L34,L34*2) -> 0 | P34: 搏击 | T34: 3 | U34: =IF(R34=0,S34+T34,S34*2+T34) -> 3
F35: =IF(D35=0,E35,E35*2) -> 0 | I35: 法医 | M35: =IF(K35=0,L35,L35*2) -> 0 | P35: 警觉 | T35: 8 | U35: =IF(R35=0,S35+T35,S35*2+T35) -> 8
F36: =IF(D36=0,E36,E36*2) -> 0 | I36: 开锁 | M36: =IF(K36=0,L36,L36*2) -> 0 | P36: 追踪 | R36: √ | U36: =IF(R36=0,S36+T36,S36*2+T36) -> 0
F37: =IF(D37=0,E37,E37*2) -> 0 | I37: 野外求生 | M37: =IF(K37=0,L37,L37*2) -> 0 | P37: 潜行 | T37: 4 | U37: =IF(R37=0,S37+T37,S37*2+T37) -> 4
F38: =IF(D38=0,E38,E38*2) -> 0 | I38: 药剂学 | M38: =IF(K38=0,L38,L38*2) -> 0 | P38: 近战武器 | U38: =IF(R38=0,S38+T38,S38*2+T38) -> 0
F39: =IF(D39=0,E39,E39*2) -> 0 | I39: 摄影 | K39: √ | L39: 1 | M39: =IF(K39=0,L39,L39*2) -> 2 | U39: =IF(R39=0,S39+T39,S39*2+T39) -> 0
F40: =IF(D40=0,E40,E40*2) -> 0 | I40: 飞机驾驶 | L40: 4 | M40: =IF(K40=0,L40,L40*2) -> 4 | U40: =IF(R40=0,S40+T40,S40*2+T40) -> 0
F41: =IF(D41=0,E41,E41*2) -> 0 | M41: =IF(K41=0,L41,L41*2) -> 0 | U41: =IF(R41=0,S41+T41,S41*2+T41) -> 0
B43: 坚毅之源 | L43: 联系人及游戏记录
B44: 已经疯魔的西奥多叔叔 | L44: 该人物卡转换自COC第七版中的示例人物卡哈维·沃尔特，并稍作了些修改

Sheet 职业
B1: 职业列表 | C1: 信誉等级 | F1: 职业技能
A2: 0 | F2: 无 | G2: 无 | H2: 无 | I2: 无 | J2: 无 | K2: 无 | L2: 无 | M2: 无 | N2: 无 | O2: 无
A3: 1 | B3: 精神病学家 | C3: 3 | D3: ~ | E3: 4 | F3: 生物学 | G3: 语言 | H3: 文献查阅 | I3: 医学 | J3: 药剂学 | K3: 精神分析 | L3: 察言观色 | M3: 社交 | N3: 社交 | O3: 无 | T3: 列 | U3: 本职技能 | V3: 备注
A4: 2 | B4: ▽古玩家 | C4: 2 | D4: ~ | E4: 5 | F4: 建筑学 | G4: 艺术史 | H4: 议价 | I4: 历史 | J4: 语言 | K4: 法律 | L4: 文献查阅 | M4: 调查 | N4: 无 | O4: 无 | T4: 1 | U4: =LOOKUP(人物卡!$E$6,职业!$A$3:$A$25,职业!F$3:F$25) -> #N/A | V4: 1
A5: 3 | B5: 考古学家 | C5: 4 | D5: ~ | E5: 5 | F5: 考古学 | G5: 运动 | H5: 证物采集 | I5: 急救 | J5: 历史 | K5: 语言 | L5: 文献查阅 | M5: 调查 | N5: 调查 | O5: 骑术 | T5: 2 | U5: =LOOKUP(人物卡!$E$6,职业!$A$3:$A$25,职业!G$3:G$25) -> #N/A | V5: 1
A6: 4 | B6: ▽艺术家 | C6: 1 | D6: ~ | E6: 4 | F6: 建筑学 | G6: 艺术史 | H6: 艺术 | I6: 手艺 | J6: 伪装 | K6: 奉承 | L6: 摄影 | M6: 察言观色 | N6: 学术或社交 | O6: 学术或社交 | T6: 3 | U6: =LOOKUP(人物卡!$E$6,职业!$A$3:$A$25,职业!H$3:H$25) -> #N/A | V6: 1
A7: 5 | B7: ▽作家 | C7: 1 | D7: ~ | E7: 3 | F7: 艺术 | G7: 历史 | H7: 语言 | I7: 文献查阅 | J7: 口述采访 | K7: 察言观色 | L7: 任意 | M7: 任意 | N7: 任意 | O7: 无 | T7: 4 | U7: =LOOKUP(人物卡!$E$6,职业!$A$3:$A$25,职业!I$3:I$25) -> #N/A | V7: 1
A8: 6 | B8: 神职人员 | C8: 2 | D8: ~ | E8: 5 | F8: 历史 | G8: 语言 | H8: 文献查阅 | I8: 精神分析 | J8: 察言观色 | K8: 安抚 | L8: 神学 | M8: 社交 | N8: 无 | O8: 无 | T8: 5 | U8: =LOOKUP(人物卡!$E$6,职业!$A$3:$A$25,职业!J$3:J$25) -> #N/A | V8: 1
A9: 7 | B9: 罪犯 | C9: 0 | D9: ~ | E9: 4 | F9: 议价 | G9: 威胁 | H9: 开锁 | I9: 搏击 | J9: 警觉 | K9: 追踪 | L9: 潜行 | M9: 底层社会 | N9: 社交或技术 | O9: 无 | T9: 6 | U9: =LOOKUP(人物卡!$E$6,职业!$A$3:$A$25,职业!K$3:K$25) -> #N/A | V9: 1
A10: 8 | B10: ▽风雅子弟 | C10: 3 | D10: + | F10: 信誉等级 | G10: 奉承 | H10: 骑术 | I10: 任意 | J10: 任意 | K10: 任意 | L10: 任意 | M10: 任意 | N10: 无 | O10: 无 | T10: 7 | U10: =LOOKUP(人物卡!$E$6,职业!$A$3:$A$25,职业!L$3:L$25) -> #N/A | V10: 1
A11: 9 | B11: ▽医生 | C11: 4 | D11: ~ | E11: 6 | F11: 会计 | G11: 生物学 | H11: 急救 | I11: 法医 | J11: 语言 | K11: 医学 | L11: 亚欧积雪 | M11: 察言观色 | N11: 安抚 | O11: 无 | T11: 8 | U11: =LOOKUP(人物卡!$E$6,职业!$A$3:$A$25,职业!M$3:M$25) -> #N/A | V11: 1
A12: 10 | B12: 流浪汉 | C12: 0 | F12: 运动 | G12: 议价 | H12: 偷窃 | I12: 野外求生 | J12: 警觉 | K12: 潜行 | L12: 底层社会 | M12: 无 | N12: 无 | O12: 无 | T12: 9 | U12: =LOOKUP(人物卡!$E$6,职业!$A$3:$A$25,职业!N$3:N$25) -> #N/A | V12: 1
A13: 11 | B13: ▽记者 | C13: 2 | D13: ~ | E13: 4 | F13: 警方交谈 | G13: 伪装 | H13: 证物采集 | I13: 语言 | J13: 口述采访 | K13: 摄影 | L13: 察言观色 | M13: 安抚 | N13: 追踪 | O13: 社交 | T13: 10 | U13: =LOOKUP(人物卡!$E$6,职业!$A$3:$A$25,职业!O$3:O$25) -> #N/A | V13: 1
A14: 12 | B14: 军人 | C14: 2 | D14: ~ | E14: 4 | F14: 运动 | G14: 枪械 | H14: 威胁 | I14: 野外求生 | J14: 搏击 | K14: 近战武器 | L14: 无 | M14: 无 | N14: 无 | O14: 无 | P14: 不同兵种职业能力不同，具体参阅规则书
A15: 13 | B15: 医务兵 | C15: 2 | D15: ~ | E15: 4 | F15: 运动 | G15: 枪械 | H15: 威胁 | I15: 野外求生 | J15: 搏击 | K15: 近战武器 | L15: 急救 | M15: 医学 | N15: 安抚 | O15: 无
A16: 14 | B16: 工程兵 | C16: 2 | D16: ~ | E16: 4 | F16: 运动 | G16: 枪械 | H16: 威胁 | I16: 野外求生 | J16: 搏击 | K16: 近战武器 | L16: 驾驶 | M16: 爆破 | N16: 机械维修 | O16: 无
A17: 15 | B17: 海军 | C17: 2 | D17: ~ | E17: 4 | F17: 运动 | G17: 枪械 | H17: 威胁 | I17: 野外求生 | J17: 搏击 | K17: 近战武器 | L17: 天文学 | M17: 机械维修 | N17: 导航 | O17: 无
A18: 16 | B18: 军官 | C18: 2 | D18: ~ | E18: 5 | F18: 运动 | G18: 枪械 | H18: 威胁 | I18: 野外求生 | J18: 搏击 | K18: 近战武器 | L18: 官僚 | M18: 特殊 | N18: 安抚 | O18: 无
A19: 17 | B19: 护士 | C19: 2 | D19: ~ | E19: 4 | F19: 生物学 | G19: 急救 | H19: 医学 | I19: 药剂学 | J19: 察言观色 | K19: 安抚 | L19: 无 | M19: 无 | N19: 无 | O19: 无 | P19: 若KP许可，可以增加官僚/奉承
A20: 18 | B20: 灵异现象研究者 | C20: 2 | D20: ~ | E20: 3 | F20: 人类学 | G20: 电器维修 | H20: 文献查阅 | I20: 机械维修 | J20: 神秘学 | K20: 摄影 | L20: 察言观色 | M20: 警觉 | N20: 无 | O20: 无
A21: 19 | B21: 飞行员 | C21: 2 | D21: ~ | E21: 3 | F21: 天文学 | G21: 驾驶 | H21: 电器维修 | I21: 机械维修 | J21: 导航 | K21: 警觉 | L21: 无 | M21: 无 | N21: 无 | O21: 无
A22: 20 | B22: ▽警探 | C22: 3 | D22: ~ | E22: 4 | F22: 运动 | G22: 警方交谈 | H22: 驾驶 | I22: 证物采集 | J22: 枪械 | K22: 审讯 | L22: 法律 | M22: 察言观色 | N22: 警觉 | O22: 无
A23: 21 | B23: 私家侦探 | C23: 2 | D23: ~ | E23: 3 | F23: 会计 | G23: 伪装 | H23: 驾驶 | I23: 法律 | J23: 开锁 | K23: 摄影 | L23: 察言观色 | M23: 安抚 | N23: 搏击 | O23: 追踪
A24: 22 | B24: ▽教授 | C24: 3 | D24: ~ | E24: 5 | F24: 官僚 | G24: 语言 | H24: 文献查阅 | I24: 社交 | J24: 学术 | K24: 学术 | L24: 学术 | M24: 无 | N24: 无 | O24: 无 | P24: 任意1种社交能力，以及任意3种学术能力（包括用于学术研究的天文学和化学）
A25: 23 | B25: 科学家 | C25: 3 | D25: ~ | E25: 4 | F25: 电器维修 | G25: 证物采集 | H25: 语言 | I25: 文献查阅 | J25: 摄影 | K25: 无 | L25: 无 | M25: 无 | N25: 无 | O25: 无 | P25: 下列任选2：天文学、生物学、化学、密码学、法医、地质学、物理学
B28: 会计
B29: 伪装
B30: 驾驶
B31: 法律
B32: 开锁
B33: 摄影
B34: 察言观色
B35: 安抚
B36: 搏击
B37: 追踪

Sheet 特殊规则
A1: 0 | C1: 请选择职业！
A2: 1 | B2: 精神病学家 | C2: 你可以使用医学或一个社交能力来获取不对外公开的精神治疗记录，或进入不对外开放的精神病院病房。如果你是拥有行医执照的医生（医学2级或以上），你可以用同样的方法获取医疗记录，以及进入医院病房。你可以做一个难度为3的精神分析检定来进行“精神治疗类选法”。你只需耗费1点精神分析能力池点数使精神异常的对象稳定下来。你也能恢复自己的坚毅，但是每耗费１ 点精神分析点数只能恢复1点坚毅。
A3: 2 | B3: ▽古玩家 | C3: 在一个冒险剧本中可以使用一次。你“商店的库房里” 恰好有目前调查所需的一条信息或一件物品。旧书商会有一本记载了相关知识的书籍（比如一本回忆录或者私人出版的狂人札记）、银器商人会有一把精致的匕首，而进口商会有一副“来自刚果部落的怪异面具”。你需要使用相关能力（如艺术史或文献查阅）才能记起并找到这件物品。 如果你离开了你的藏品或店铺所在的城市，你可能无法使用该能力（即使能用，也颇费周折）。除非你有一个信得过的助手能找到你要的东西，并邮寄给你……而你也愿意耐心等待邮包在一周后抵达，同时眼看着邪教徒的力量不断壮大。 守秘人有权禁止你拥有强大的神器或效果卓著的魔法书之类的物品，也有权否决任何对物品的滥用或无理的要求。他同样有权给你的物品添加某些副作用。
A4: 3 | B4: 考古学家 | C4: 你能用考古学或一个合适的社交能力进入博物馆的库房或者接触文物，但是不能将它们带走。如果你有学位证书（考古学2+，且信誉等级3+），你可以进入大学图书馆的闭架书库。
A5: 4 | B5: ▽艺术家 | C5: 每当冒险中有一段较长的休息时间，你都可以将一项能力的能力池点数全部恢复。该能力应当代表你所擅长的艺术形式（如艺术、建筑学、手艺、摄影等），每次游戏聚会中使用不超过4次。这代表你把时间花在了排演曲目、打草稿画素描，或者诸如此类的行为上。如果艺术家没有时间或资源磨练技艺，守秘人不得允许他恢复能力池点数。
A6: 5 | B6: ▽作家 | C6: 你可以利用冒险中的任何休息时间将一项学术能力的能力池点数全部恢复，每次游戏聚会中使用不超过4次。这代表你把时间花在了阅读、检查笔记和档案，或者诸如此类的行为上。如果调查员没有时间或没有材料可以阅读，守秘人不得允许他恢复能力池点数。换言之，《克苏鲁迷踪》的冒险充斥着文献资料， 它们有时会引诱一位合格的作家告诉同伴：“你们去查看这座房子的其他部分吧，我要花一两个小时翻翻这些书籍了。”
A7: 6 | B7: 神职人员 | C7: 你能用神学或安抚获取公众很难接触到的教会记录。当然，单凭神职人员的身份无法让你浏览梵蒂冈图书馆的Z类藏品或者类似的秘密档案，但如果你愿意耗费足够多的点数，仁慈的守秘人或许会网开一面。如果你表明自己神职人员的身份、或身穿神职人员的传统服装， 你可以通过与一位教友（不得是其他调查员）进行攀谈，将一项社交能力的能力池点数完全恢复。每次游戏聚会中只可使用1次。在原旨风格中，精神分析不是你的本职技能。
A8: 7 | B8: 罪犯 | C8: 在藏匿、偷窃或追踪能力的能力池中拥有点数的罪犯，在为这三项能力做检定时，可以在掷骰之后耗用点数。掷骰后每耗费2点，检定结果加1。这仅适用于你不受干扰，并且没有被直接察觉的情况。该特殊能力不能在对抗检定中使用。你必须描述事情差点搞砸、而在千钧一发之际你又如何及时弥补，或者只是靠着好运才得以侥幸成功的过程。 黑手党成员可以免费获得1级语言（意大利语）能力。守秘人可自行决定是否用相似的规则处理类似犯罪组织的成员。
A9: 8 | B9: ▽风雅子弟 | C9: 无论从事什么行当，你都可以耗用信誉等级能力池来找到你的私人关系。这些联系人通常是亲戚、同学、校友，或者属于同一社会阶层的、与你类似的人物。
A10: 9 | B10: ▽医生 | C10: 你能用医学或安抚能力获取非公开的医疗记录。如果你隶属于医院、疗养院或其他机构，那么你无需检定就能使用安抚能力自动说服他人，使其允许你进出你工作机构中从药柜到冷冻室的任何区域。 你从能力池中每耗费1点急救点数可治疗3点健康。你对自己使用急救时，每耗费1点急救点数可治疗2点健康。你只需耗费1点急救点数就能稳定“重伤”。
A11: 10 | B11: 流浪汉 | C11: 除了警觉和底层社会能力的一般用途，你还能用这两个能力看懂流浪汉们留下的暗记，弄清陌生小镇的当地情况。底层社会能力可以帮你找到同为流浪汉的联系人。你可使用的其他联系人包括共产党员 （例如“世界产业工人联盟”这类在各地开展工作的劳工组织）、友善的铁路护路工、慈善义工、某位容易听信他人的当地妇女等等。
A12: 11 | B12: ▽记者 | C12: 你能用安抚进入收藏旧报纸的资料库。在你自己的报社，同样的方法可以让资料员帮你找到相关的文章。记者同行也会向你透露小道消息，只要你不是他们的直接竞争对手。
A13: 12 | B13: 军人 | C13: 只要你的坚毅能力池点数大于0，你就可以从安抚能力池中耗费2点，让惊惧或行为反常的角色恢复平静。 如果你仍在服役，你可以使用任意一项社交能力获准进入本国的军事设施，只有被列为最高机密的基地除外。当然，若想不为人知地进入，那就要另作打算了。 如果你是战场老兵，除非你的坚毅或健康能力池点数低于-5，否则你的战斗能力（运动、枪械、搏击和近战武器）的检定难度以及对方的命中阈值不会+1。如果你是战场老兵，你的坚毅等级最高不得超过10；但是在面对某些威胁时，你的坚毅检定难度可以有所降低。
... A24: 23 | B24: 科学家 | C24: 你能进入与你目前的研究相关的实验室，用信誉等级让同行或同事在其他实验室里帮你进行实验或搭建专门的仪器设备。如果有学位证书（信誉等级大于等于3，以下能力之一大于等于2：天文学、生物学、化学、地质学、物理学）， 你能进入大学图书馆的闭架书库。

Sheet 信誉等级
A1: 信誉等级 | B1: 经济阶层 | C1: 典型标志 | D1: 年收入范围
A2: 0 | B2: 赤贫 | C2: 流浪汉；衣衫褴褛；居无定所；接受救济；拾荒 | D2: $0-$150
A3: 1 | B3: 底层阶级 | C3: 门房，雇农，仆人；戴软帽；住廉价旅馆、公寓单人间，或与亲戚合住；坐公共汽车；吃罐头汤食或罐头豆子） | D3: $150-$250
A4: 2 | B4: 工人阶级 | C4: 在工厂上班或熟练的技工；帽子带沿；公寓的租户；坐公共汽车；大部分时间有肉吃 | D4: $250-$1,250
A5: 3 | B5: 中产阶级下层 | C5: 职员或精良的技工；系领带；住老旧公寓；开旧车；周日餐桌食物不错 | D5: $1,250-$1,500
A6: 4 | B6: 中产阶级 | C6: 管理者，资历较浅的专业从业人员；有一套考究的正装；住独栋平房或体面的公寓；开中档车辆；偶尔下餐馆；雇佣兼职的清洁女工 | D6: $1,500-$3,000
A7: 5 | B7: 中产阶级上层 | C7: 专业从业人员；穿裁制的套装；住考究的别墅或公寓；开新车或有两辆车；无论是在家或在外，都吃精美的菜肴；有住家的仆佣 | D7: $3,000-$10,000
A8: 6 | B8: 上层阶级 | C8: 不必工作就能维持生活；独一无二的专业从业人员；穿高级订制的套装；住别墅或顶层豪华公寓；开豪车；精肴美馔；有多位仆人 | D8: $10,000- $75,000
A9: 7 | B9: 非常富有 | C9: 有土地或有工业财富的士绅；有精美绝伦的珠宝；住庄园宅邸；有私人游艇和飞机；雇四星级私人大厨；有等级分明的家仆班子 | D9: $75,000+

Sheet 武器列表
A1: 枪械列表
A2: 武器名称 | B2: 伤害调整值 | C2: 装弹数量 | D2: 价格 | E2: 备注
A3: 韦伯利-斯科特警用.32ACP自动手枪（1906） | B3: +0 | C3: 8 | D3: 10
A4: TT-3托卡列夫7.62毫米自动手枪（1933） | B4: +0 | C4: 8 | D4: 45 | E4: 苏联军用/警用手枪
A5: 南部十四式8毫米自动手枪（1925） | B5: +0 | C5: 8 | D5: 40 | E5: 日本军用手枪
A6: 毛瑟“扫把柄”7.62毫米自动手枪（1896）* | B6: +0 | C6: 10 | D6: 50
A7: 雷明顿.41双管袖珍手枪（1866） | B7: +0 | C7: 2 | D7: 20 | E7: 若要在携带者身上发现此枪，检定难度+1；射程仅为近身范围
A8: 柯尔特警用.32左轮枪（1907） | B8: +0 | C8: 6 | D8: 15 | E8: 美国警用手枪
A9: 沃尔特PPK.32自动手枪（1931） | B9: +0 | C9: 7 | D9: 70
A10: 雷明顿M34式.22LR运动步枪（1932） | B10: +0 | C10: 20 | D10: 45
A11: 曼利夏-卡尔卡诺M1891式6.5毫米手动卡宾枪（1891） | B11: +0 | C11: 6 | D11: 20 | E11: 意大利战斗步枪；该数据同样可用于日本的有坂四四式步骑枪
A12: 温彻斯特M1912式20号口径唧筒霰弹枪（1912） | B12: +0 | C12: 5 | D12: 50
A13: 雷明顿M32式20号口径霰弹枪（1932） | B13: +0 | C13: 2 | D13: 35 | E13: 双管
A14: 威利12号口径信号枪（1882） | B14: +1 | C14: 1 | D14: 30 | E14: 仅在近身（无伤害加值）或近距离内才会造成伤害；如击中远距离以内的易燃物，会使其燃烧
A15: 柯尔特M1911A1式.45 ACP自动手枪（1926） | B15: +1 | C15: 7 | D15: 50 | E15: 美国军用手枪；所有修理或解除卡壳的检定难度均-1
A16: 鲁格P08式9毫米自动手枪（1908） | B16: +1 | C16: 8 | D16: 50 | E16: 德国军用手枪
A17: 沃尔特P38式9毫米自动手枪（1938） | B17: +1 | C17: 8 | D17: 75 | E17: 德国军用手枪
A18: FN勃朗宁大火力9毫米半自动手枪（1935） | B18: +1 | C18: 13 | D18: 75
A19: 韦伯利1号MK4型.455 SAA左轮手枪（1915） | B19: +1 | C19: 6 | D19: 25 | E19: 英国军用手枪
A20: 史密斯-威森.38特种左轮手枪（1902） | B20: +1 | C20: 6 | D20: 30 | E20: 美国警用手枪
A21: 史密斯-威森27型.357马格南左轮手枪（1927） | B21: +1 | C21: 6 | D21: 80
A22: 汤普森M1921冲锋枪（1921） | B22: +1 | C22: 20、30、50、100 | D22: 200
A23: 施迈瑟MP28冲锋枪（1928） | B23: +1 | C23: 32 | D23: 200
A24: 毛瑟98K式7.92毫米步枪（1935） | B24: +1 | C24: 5 | D24: 125 | E24: 德国战斗步枪；该数据同样可用于苏联莫辛-纳甘M10式7.62毫米战斗步枪（价格为100美元）
A25: M1加兰德.30-06步枪（1936） | B25: +1 | C25: 8 | D25: 120 | E25: 美国战斗步枪
A26: 李-恩菲尔德3型.303步枪（1907） | B26: +1 | C26: 10 | D26: 100 | E26: 英国战斗步枪
A27: 温彻斯特M1912式12口径唧筒霰弹枪（1912） | B27: +1 | C27: 5 | D27: 50
A28: 雷明顿M32式12口径霰弹枪（1932） | B28: +1 | C28: 2 | D28: 35 | E28: 双管
A29: 赫兰-赫兰“双管急速型”（Double Express）.600猎象步枪（1903） | B29: +2 | C29: 2 | D29: 500 | E29: 伤害值+2；下一回合，射击者必须通过难度为3的运动检定才能保持站立。这一动作将占据该回合的行动
A30: 勃朗宁自动步枪（BAR）.303机枪（1918） | B30: +2 | C30: 20 | D30: 500 | E30: 伤害值+2；需使用双脚架，并以匍匐姿势射击
A31: 拳脚 | B31: -2 | C31: / | D31: /
A32: 小型临时武器 | B32: -1 | C32: / | D32: /
A33: 蒙皮短棒 | B33: -1 | C33: / | D33: /
A34: 鞭子 | B34: -1 | C34: / | D34: /
A35: 警棍 | B35: -1 | C35: / | D35: /
A36: 小刀 | B36: -1 | C36: / | D36: /
A37: 大型临时武器 | B37: +0 | C37: / | D37: /
A38: 砍刀 | B38: +0 | C38: / | D38: /
A39: 粗重的棍棒 | B39: +0 | C39: / | D39: /
A40: 通火棍 | B40: +0 | C40: / | D40: /
...

Sheet 心智支柱
A1: 序号 | B1: 心智支柱
A2: 1 | B2: 宗教信仰（可以是具体的教派，也可以是对仁慈、理性的神祇的一般性信仰）
A3: 2 | B3: 家族（尤其是家族荣誉、血统 纯正之类）
A4: 3 | B4: 人的尊严与价值
A5: 4 | B5: 科学的进步或理性的价值
A6: 5 | B6: 物理定律和科学认知的客观性
A7: 6 | B7: 善、美或“自然”（作为抽象概念 ）的价值
A8: 7 | B8: 人类禀有的内在之善
A9: 8 | B9: 道德原则
A10: 9 | B10: 美学或艺术的至高原则
A11: 10 | B11: 伊壁鸠鲁主义，不辜负自己的生命
A12: 11 | B12: 爱国情操与民族美德
A13: 12 | B13: 对故乡城镇的热爱
B14: 。。。

Sheet 动力
A1: 序号 | B1: 动力 | C1: 说明 | D1: 建议职业
A2: 1 | B2: 冒险 | C2: 没有什么比刺激的行动、战斗和奇怪的新经历更能吸引你了。你对肾上腺素的刺激渴求成瘾，如果只有怪物的脓水才能消除这种饥渴，那就去找吧！拒绝冒险、“谨慎行事”无异于承认你过去的整个生活毫无意义。 | D2: 罪犯、军人、灵异现象研究者和飞行员。
A3: 2 | B3: 好古 | C3: 只有投身于死寂的过去，你才觉得自己真正活着。发现历史的真相，或者只是欣赏一下古老而美丽的房屋与物品，就是活着的全部意义。你觉得，仅仅因为不太可口就漠视过去，可真是粗蛮而又短暂的现代品味。 | D3: 古玩家、考古学家、神职人员和教授。
A4: 3 | B4: 自大 | C4: 你最终的成功，将是最有力的证明——你一定会成功，因为只有你矢志必得。约束无名之辈的陈规陋习对你毫不适用，而那些家伙的退缩和畏惧也同样不会沾染在你的身上。 | D4: 精神病学家和科学家。
A5: 4 | B5: 艺术的敏感 | C5: 你已经意识到了世界那令人敬畏的、超自然的本质，而这正是你希望用艺术的手段再现的东西。你必须追寻缪斯的足迹，就像一团在她手中塑造成型的粘土。你对灵感的渴求不能被任何事情阻断，尤其是世俗的烦扰。 | D5: 艺术家、作家和风雅子弟。
A6: 5 | B6: 坏运气 | C6: 这些事总是一再找上你，在你挖出一个小雕像、借宿时睡错地方或决定抢劫一个可怕的老头之后，你的运气就开始变差了。坏运气本质上相当于受到诅咒（第74页解释了如何将坏运气或受到诅咒与动力的相关规则配合使用）。 | D6: 罪犯和流浪汉。
A7: 6 | B7: 好奇 | C7: 每当遇到神秘事件时，你总是忍不住进行调查。去他妈的危险，有什么事情不对劲，你一定得弄明白！如果放着不管，你绝对没法安心。 | D7: 记者、灵异现象研究者、警探、私家侦探和科学家。
A8: 7 | B8: 责任 | C8: 你明知这么做危险而且鲁莽，但总得有人走下那些台阶，或去捣毁那个邪教团体。那个人就是你。如果你袖手旁观，事情只会继续恶化。你若不去做，还有谁能行？那些朝九晚五、无所事事，数着日子等着领退休金的懒人？别说笑了。 | D8: 神职人员、医生、军人和警探。
A9: 8 | B9: 无聊 | C9: 也许有一段经历你再也无法重获，也许有一段冒险你在通俗小说里读过。别的一切事情你都尝试过了，全都没有用，没有什么还能让你的心真正挂怀。即使那件事会让你丧命，那又有什么关系？至少它带来了变化。 | D9: 艺术家、风雅子弟和军人。
A10: 9 | B10: 追随者 | C10: 这其实不是你的主意，你希望报告里能提到这点。但是某个对你来说很重要的人走进了那条隧道。你最好跟上，才好保证对方安然无恙，或者确保下次他们不会让别人守着那部户外电话。 | D10: 医生、军人和警探。
A11: 10 | B11: 血脉相承 | C11: 说实话，你不明白自己为什么不断回到腐朽的墓穴，或是仔细研读古代文本。但是你的家族里世代流传着古怪的行为，外人显然无法理解。 | D11: 古玩家和风雅子弟。
A12: 11 | B12: 复仇 | C12: 有什么东西伤害了你或你在意的人。因此，你必须不惜一切代价毁灭它、焚烧它、打倒它、揭露它……任何能帮助你实现复仇的线索，你都必须追查到底。 | D12: 罪犯和私家侦探。
A13: 12 | B13: 学术研究 | C13: 真正的学者就应该揭示世界的真相。因此，你把全部时间耗费在图书馆里；因此，你前往偏远、孤立的地区追寻邪教团体唯一的幸存者；因此，你学习人类的发声器官无法诵读的语言。无论是为了寻求终身教职、获得同行的赞许，或者只为了增广见闻所带来的满足感，你探究的目的都是为了发现表象之下隐藏的那个共通模式。 | D13: 考古学家、教授和科学家。
... A15: 14 | B15: 认知的渴求 | C15: 你必须——你必须！——知晓宇宙的秘密！这不是聊胜于无的论文脚注，而是通往真相的征途。你无意于增进人类的认知：平庸大众既不愿也不配了解这个世界背后的东西。只有你（或许还有少数志同道合的伙伴）热切地渴望掌握这类秘密，只有你愿不惜一切代价获得真相。 | D15: 考古学家、灵异现象研究者和教授。
